Workbook

Sheet 2 T-test
A1: t-Test: Two-Sample Assuming Unequal Variances
B3: Variable 1 | C3: Variable 2
A4: Mean | B4: 143.78171 | C4: 106.69372
A5: Variance | B5: 5293.9995 | C5: 3962.1725
A6: Observations | B6: 339 | C6: 9661
A7: Hypothesized Mean Difference | B7: 0
A8: df | B8: 356
A9: t Stat | B9: 9.2642897
A10: P(T<=t) one-tail | B10: 9.5276796e-19
A11: t Critical one-tail | B11: 1.6491451
A12: P(T<=t) two-tail | B12: 1.9055359e-18
A13: t Critical two-tail | B13: 1.96665

Sheet Correlation
B1: Air temperature [K] | C1: Process temperature [K] | D1: Rotational speed [rpm] | E1: Torque [Nm] | F1: Tool wear [min]
A2: Air temperature [K] | B2: 1
A3: Process temperature [K] | B3: 0.87610716 | C3: 1
A4: Rotational speed [rpm] | B4: 0.022670459 | C4: 0.019276714 | D4: 1
A5: Torque [Nm] | B5: -0.013777823 | C5: -0.014060613 | D5: -0.87502709 | E5: 1
A6: Tool wear [min] | B6: 0.013852828 | C6: 0.013487517 | D6: 0.00022308484 | E6: -0.0030927814 | F6: 1

Sheet ai4i2020
A1: UDI | B1: Product ID | C1: Type | D1: Air temperature [K] | E1: Process temperature [K] | F1: Rotational speed [rpm] | G1: Torque [Nm] | H1: Tool wear [min] | I1: Machine failure | J1: TWF | K1: HDF | L1: PWF | M1: OSF | N1: RNF | P1: =COUNTIFS(J:J, 1, H:H, ">=120") -> 46
A2: 1 | B2: M14860 | C2: M | D2: 298.1 | E2: 308.6 | F2: 1551 | G2: 42.8 | H2: 0 | I2: 0 | J2: 0 | K2: 0 | L2: 0 | M2: 0 | N2: 0 | P2: =COUNTIFS(M:M, 1, G:G, ">=55") -> 66
A3: 2 | B3: L47181 | C3: L | D3: 298.2 | E3: 308.7 | F3: 1408 | G3: 46.3 | H3: 3 | I3: 0 | J3: 0 | K3: 0 | L3: 0 | M3: 0 | N3: 0
A4: 3 | B4: L47182 | C4: L | D4: 298.1 | E4: 308.5 | F4: 1498 | G4: 49.4 | H4: 5 | I4: 0 | J4: 0 | K4: 0 | L4: 0 | M4: 0 | N4: 0
A5: 4 | B5: L47183 | C5: L | D5: 298.2 | E5: 308.6 | F5: 1433 | G5: 39.5 | H5: 7 | I5: 0 | J5: 0 | K5: 0 | L5: 0 | M5: 0 | N5: 0
A6: 5 | B6: L47184 | C6: L | D6: 298.2 | E6: 308.7 | F6: 1408 | G6: 40 | H6: 9 | I6: 0 | J6: 0 | K6: 0 | L6: 0 | M6: 0 | N6: 0
A7: 6 | B7: M14865 | C7: M | D7: 298.1 | E7: 308.6 | F7: 1425 | G7: 41.9 | H7: 11 | I7: 0 | J7: 0 | K7: 0 | L7: 0 | M7: 0 | N7: 0
A8: 7 | B8: L47186 | C8: L | D8: 298.1 | E8: 308.6 | F8: 1558 | G8: 42.4 | H8: 14 | I8: 0 | J8: 0 | K8: 0 | L8: 0 | M8: 0 | N8: 0
A9: 8 | B9: L47187 | C9: L | D9: 298.1 | E9: 308.6 | F9: 1527 | G9: 40.2 | H9: 16 | I9: 0 | J9: 0 | K9: 0 | L9: 0 | M9: 0 | N9: 0
A10: 9 | B10: M14868 | C10: M | D10: 298.3 | E10: 308.7 | F10: 1667 | G10: 28.6 | H10: 18 | I10: 0 | J10: 0 | K10: 0 | L10: 0 | M10: 0 | N10: 0
A11: 10 | B11: M14869 | C11: M | D11: 298.5 | E11: 309 | F11: 1741 | G11: 28 | H11: 21 | I11: 0 | J11: 0 | K11: 0 | L11: 0 | M11: 0 | N11: 0
A12: 11 | B12: H29424 | C12: H | D12: 298.4 | E12: 308.9 | F12: 1782 | G12: 23.9 | H12: 24 | I12: 0 | J12: 0 | K12: 0 | L12: 0 | M12: 0 | N12: 0
A13: 12 | B13: H29425 | C13: H | D13: 298.6 | E13: 309.1 | F13: 1423 | G13: 44.3 | H13: 29 | I13: 0 | J13: 0 | K13: 0 | L13: 0 | M13: 0 | N13: 0
A14: 13 | B14: M14872 | C14: M | D14: 298.6 | E14: 309.1 | F14: 1339 | G14: 51.1 | H14: 34 | I14: 0 | J14: 0 | K14: 0 | L14: 0 | M14: 0 | N14: 0
... A10001: 10000 | B10001: M24859 | C10001: M | D10001: 299 | E10001: 308.7 | F10001: 1500 | G10001: 40.2 | H10001: 30 | I10001: 0 | J10001: 0 | K10001: 0 | L10001: 0 | M10001: 0 | N10001: 0

Sheet Control
A1: Live Tool Wear | B1: Proocess Average | C1: Upper Control Limit | D1: Maintenance Alert
A2: 0 | B2: 104.5 | C2: 120 | D2: =IF(A2>120, "REPLACE TOOL", "OK") -> OK
A3: 3 | B3: 104.5 | C3: 120 | D3: =IF(A3>120, "REPLACE TOOL", "OK") -> OK
A4: 5 | B4: 104.5 | C4: 120 | D4: =IF(A4>120, "REPLACE TOOL", "OK") -> OK
A5: 7 | B5: 104.5 | C5: 120 | D5: =IF(A5>120, "REPLACE TOOL", "OK") -> OK
A6: 9 | B6: 104.5 | C6: 120 | D6: =IF(A6>120, "REPLACE TOOL", "OK") -> OK
A7: 11 | B7: 104.5 | C7: 120 | D7: =IF(A7>120, "REPLACE TOOL", "OK") -> OK
A8: 14 | B8: 104.5 | C8: 120 | D8: =IF(A8>120, "REPLACE TOOL", "OK") -> OK
A9: 16 | B9: 104.5 | C9: 120 | D9: =IF(A9>120, "REPLACE TOOL", "OK") -> OK
A10: 18 | B10: 104.5 | C10: 120 | D10: =IF(A10>120, "REPLACE TOOL", "OK") -> OK
A11: 21 | B11: 104.5 | C11: 120 | D11: =IF(A11>120, "REPLACE TOOL", "OK") -> OK
A12: 24 | B12: 104.5 | C12: 120 | D12: =IF(A12>120, "REPLACE TOOL", "OK") -> OK
A13: 29 | B13: 104.5 | C13: 120 | D13: =IF(A13>120, "REPLACE TOOL", "OK") -> OK
... A200: 114 | B200: 104.5 | C200: 120 | D200: =IF(A200>120, "REPLACE TOOL", "OK") -> OK

Sheet ANOVA
A1: TWF Torque | B1: HDF Torque | C1: OSF Torque
A2: 41.3 | B2: 62.4 | C2: 65.7
A3: 35.8 | B3: 46.8 | C3: 60.7 | F3: Anova: Single Factor
A4: 37.7 | B4: 47.3 | C4: 52.3
A5: 36.1 | B5: 49.3 | C5: 58.8 | F5: SUMMARY
A6: 31 | B6: 44 | C6: 56.8 | F6: Groups | G6: Count | H6: Sum | I6: Average | J6: Variance
A7: 38.2 | B7: 59.1 | C7: 56.2 | F7: TWF Torque | G7: 46 | H7: 1740.5 | I7: 37.836957 | J7: 105.62149
A8: 23.4 | B8: 48.4 | C8: 56.7 | F8: HDF Torque | G8: 115 | H8: 6114.2 | I8: 53.166957 | J8: 38.731881
A9: 37.5 | B9: 62.4 | C9: 49.8 | F9: OSF Torque | G9: 98 | H9: 5720.3 | I9: 58.370408 | J9: 35.326229
A10: 41.9 | B10: 58 | C10: 62
A11: 47.6 | B11: 58.2 | C11: 55.6
A12: 19.8 | B12: 54.9 | C12: 56.4 | F12: ANOVA
A13: 39 | B13: 51.7 | C13: 61.2 | F13: Source of Variation | G13: SS | H13: df | I13: MS | J13: F | K13: P-value | L13: F crit
A14: 46.4 | B14: 45.1 | C14: 57.1 | F14: Between Groups | G14: 13316.67 | H14: 2 | I14: 6658.3348 | J14: 135.33366 | K14: 7.9078616e-41 | L14: 3.0310637
A15: 37.3 | B15: 46.3 | C15: 52.5 | F15: Within Groups | G15: 12595.046 | H15: 256 | I15: 49.199398
A16: 34.4 | B16: 47.8 | C16: 74.5
A17: 29 | B17: 62.8 | C17: 49.1 | F17: Total | G17: 25911.715 | H17: 258
A18: 30.4 | B18: 57.4 | C18: 53.8
A19: 45.3 | B19: 61.2 | C19: 53.3
A20: 40.9 | B20: 48 | C20: 69.4
A21: 46 | B21: 55.6 | C21: 61
A22: 35.9 | B22: 44.4 | C22: 52.9
A23: 35 | B23: 60.6 | C23: 61
A24: 48 | B24: 47.5 | C24: 58.8
A25: 54.8 | B25: 51.5 | C25: 53.6
A26: 65.3 | B26: 49.2 | C26: 50.4
A27: 30.5 | B27: 46.1 | C27: 53.6
A28: 37.9 | B28: 54.8 | C28: 48.9
A29: 37.8 | B29: 53.2 | C29: 60.7
... A47: 16.2 | B47: 48.2 | C47: 54.6
B48: 68.2 | C48: 54.2
B49: 57.3 | C49: 61
B50: 48.2 | C50: 53
B51: 57.6 | C51: 56.8
B52: 65.5 | C52: 58.7
B53: 45.1 | C53: 62.5
B54: 51.6 | C54: 59.9
B55: 50.9 | C55: 70.5
B56: 45.5 | C56: 53.8
B57: 58.5 | C57: 46.3
...

Sheet Measure
A1: Total Records | B1: =COUNTA(ai4i2020!A2:A10001) -> 10000
A2: Total Failures | B2: =SUM(ai4i2020!I3:I10001) -> 339
A3: Baeline Failure Rate | B3: =B2*100/B1 -> 3.39
A9: Summary Table
A10: HDF | B10: =SUM(ai4i2020!K$2:K$1048576) -> 115
A11: OSF | B11: =SUM(ai4i2020!M$2:M$1048576) -> 98
A12: PWF | B12: =SUM(ai4i2020!L$2:L$1048576) -> 95
A13: TWF | B13: =SUM(ai4i2020!J5:J10004) -> 46
A14: RNF | B14: =SUM(ai4i2020!N$2:N$1048576) -> 19
